Question: Which is the correct test patch that can reproduce the issues described in the problem statement?
Problem statement: Issue when passing empty lists/arrays to WCS transformations\nThe following should not fail but instead should return empty lists/arrays:\r\n\r\n```\r\nIn [1]: from astropy.wcs import WCS\r\n\r\nIn [2]: wcs = WCS('2MASS_h.fits')\r\n\r\nIn [3]: wcs.wcs_pix2world([], [], 0)\r\n---------------------------------------------------------------------------\r\nInconsistentAxisTypesError                Traceback (most recent call last)\r\n<ipython-input-3-e2cc0e97941a> in <module>()\r\n----> 1 wcs.wcs_pix2world([], [], 0)\r\n\r\n~/Dropbox/Code/Astropy/astropy/astropy/wcs/wcs.py in wcs_pix2world(self, *args, **kwargs)\r\n   1352         return self._array_converter(\r\n   1353             lambda xy, o: self.wcs.p2s(xy, o)['world'],\r\n-> 1354             'output', *args, **kwargs)\r\n   1355     wcs_pix2world.__doc__ = \"\"\"\r\n   1356         Transforms pixel coordinates to world coordinates by doing\r\n\r\n~/Dropbox/Code/Astropy/astropy/astropy/wcs/wcs.py in _array_converter(self, func, sky, ra_dec_order, *args)\r\n   1267                     \"a 1-D array for each axis, followed by an origin.\")\r\n   1268 \r\n-> 1269             return _return_list_of_arrays(axes, origin)\r\n   1270 \r\n   1271         raise TypeError(\r\n\r\n~/Dropbox/Code/Astropy/astropy/astropy/wcs/wcs.py in _return_list_of_arrays(axes, origin)\r\n   1223             if ra_dec_order and sky == 'input':\r\n   1224                 xy = self._denormalize_sky(xy)\r\n-> 1225             output = func(xy, origin)\r\n   1226             if ra_dec_order and sky == 'output':\r\n   1227                 output = self._normalize_sky(output)\r\n\r\n~/Dropbox/Code/Astropy/astropy/astropy/wcs/wcs.py in <lambda>(xy, o)\r\n   1351             raise ValueError(\"No basic WCS settings were created.\")\r\n   1352         return self._array_converter(\r\n-> 1353             lambda xy, o: self.wcs.p2s(xy, o)['world'],\r\n   1354             'output', *args, **kwargs)\r\n   1355     wcs_pix2world.__doc__ = \"\"\"\r\n\r\nInconsistentAxisTypesError: ERROR 4 in wcsp2s() at line 2646 of file cextern/wcslib/C/wcs.c:\r\nncoord and/or nelem inconsistent with the wcsprm.\r\n```\n
Test patches: (A) from astropy.wcs import WCS\nimport numpy as np\ndef test_func():\n    try:\n        wcs = WCS('2MASS_h.fits')\n        try:\n            result = wcs.wcs_pix2world([], [], 0)\n            if isinstance(result, np.ndarray) and result.size == 0:\n                print('Issue resolved')\n            else:\n                print('Issue reproduced')\n        except Exception as e:\n            error_message = str(e)\n            if 'InconsistentAxisTypesError' in error_message:\n                print('Issue reproduced')\n            else:\n                print('Other issues')\n    except Exception as e:\n        print(f'Other issues: {e}')\ntest_func()\n(B) from astropy.wcs import WCS\nfrom astropy.io import fits\ndef test_func() -> None:\n    try:\n        wcs = WCS('2MASS_h.fits')\n        result = wcs.wcs_pix2world([], [], 0)\n        if result == ([], []):\n            print('Issue resolved')\n        else:\n            print('Other issues')\n    except Exception as e:\n        if isinstance(e, InconsistentAxisTypesError):\n            print('Issue reproduced')\n        else:\n            print('Other issues')\ntest_func()\n(C) from astropy.wcs import WCS\nimport numpy as np\ndef test_func():\n    try:\n        wcs = WCS('2MASS_h.fits')\n        result = wcs.wcs_pix2world([], [], 0)\n        if isinstance(result, np.ndarray) and result.size == 0:\n            print('Issue resolved')\n        else:\n            print('Other issues')\n    except Exception as e:\n        if 'InconsistentAxisTypesError' in str(e) or 'ncoord and/or nelem inconsistent with the wcsprm' in str(e):\n            print('Issue reproduced')\n        else:\n            print('Other issues')\ntest_func()\n(D) from astropy.wcs import WCS\nfrom astropy.io import fits\nimport numpy as np\nimport os\ndef test_func():\n    hdu = fits.PrimaryHDU()\n    hdul = fits.HDUList([hdu])\n    temp_fits_path = 'temp_test_fits.fits'\n    hdul.writeto(temp_fits_path, overwrite=True)\n    try:\n        wcs = WCS(temp_fits_path)\n        try:\n            result = wcs.wcs_pix2world([], [], 0)\n            if isinstance(result, np.ndarray) and result.size == 0:\n                print('Issue resolved')\n            else:\n                print('Other issues')\n        except Exception as e:\n            if 'InconsistentAxisTypesError' in str(e):\n                print('Issue reproduced')\n            else:\n                print('Other issues')\n    except Exception as general_exception:\n        print('Other issues')\n    os.remove(temp_fits_path)\ntest_func()
The answer is (C)

Question: Which is the correct test patch that can reproduce the issues described in the problem statement?
Problem statement: UsernameValidator allows trailing newline in usernames\nDescription\n\t\nASCIIUsernameValidator and UnicodeUsernameValidator use the regex \nr'^[\\w.@+-]+$'\nThe intent is to only allow alphanumeric characters as well as ., @, +, and -. However, a little known quirk of Python regexes is that $ will also match a trailing newline. Therefore, the user name validators will accept usernames which end with a newline. You can avoid this behavior by instead using \\A and \\Z to terminate regexes. For example, the validator regex could be changed to\nr'\\A[\\w.@+-]+\\Z'\nin order to reject usernames that end with a newline.\nI am not sure how to officially post a patch, but the required change is trivial - using the regex above in the two validators in contrib.auth.validators.\n
Test patches: (A) import re\nfrom django.core.exceptions import ValidationError\nfrom django.contrib.auth.validators import ASCIIUsernameValidator, UnicodeUsernameValidator\ndef test_func():\n    ascii_validator = ASCIIUsernameValidator()\n    unicode_validator = UnicodeUsernameValidator()\n    test_username = 'validusername\\n'\n    try:\n        ascii_validator(test_username)\n        print('Issue reproduced')\n    except ValidationError:\n        pass\n    try:\n        unicode_validator(test_username)\n        print('Issue reproduced')\n    except ValidationError:\n        pass\n    ascii_validator.regex = re.compile('\\\\A[\\\\w.@+-]+\\\\Z')\n    unicode_validator.regex = re.compile('\\\\A[\\\\w.@+-]+\\\\Z')\n    try:\n        ascii_validator(test_username)\n    except ValidationError:\n        pass\n    else:\n        print('Issue resolved')\n    try:\n        unicode_validator(test_username)\n    except ValidationError:\n        pass\n    else:\n        print('Issue resolved')\n    valid_username = 'validusername'\n    try:\n        ascii_validator(valid_username)\n        unicode_validator(valid_username)\n        print('Issue resolved')\n    except ValidationError:\n        print('Other issues')\ntest_func()\n(B) import re\nclass ASCIIUsernameValidator:\n    regex = re.compile('^[\\\\w.@+-]+$')\n    def validate(self, username):\n        if not self.regex.match(username):\n            raise ValueError('Invalid username')\nclass UnicodeUsernameValidator:\n    regex = re.compile('^[\\\\w.@+-]+$')\n    def validate(self, username):\n        if not self.regex.match(username):\n            raise ValueError('Invalid username')\nascii_validator = ASCIIUsernameValidator()\nunicode_validator = UnicodeUsernameValidator()\ntry:\n    ascii_validator.validate('validusername')\n    ascii_validator.validate('valid.username')\n    ascii_validator.validate('valid-username')\n    ascii_validator.validate('valid+username')\n    ascii_validator.validate('valid@username')\n    ascii_validator.validate('invalidusername\\n')\ntest_func('Issue reproduced')\nexcept ValueError:\ntest_func('Issue resolved')\nexcept Exception:\ntest_func('Other issues')\ntry:\n    unicode_validator.validate('validusername')\n    unicode_validator.validate('valid.username')\n    unicode_validator.validate('valid-username')\n    unicode_validator.validate('valid+username')\n    unicode_validator.validate('valid@username')\n    unicode_validator.validate('invalidusername\\n')\ntest_func('Issue reproduced')\nexcept ValueError:\ntest_func('Issue resolved')\nexcept Exception:\ntest_func('Other issues')\nclass FixedASCIIUsernameValidator:\n    regex = re.compile('\\\\A[\\\\w.@+-]+\\\\Z')\n    def validate(self, username):\n        if not self.regex.match(username):\n            raise ValueError('Invalid username')\nclass FixedUnicodeUsernameValidator:\n    regex = re.compile('\\\\A[\\\\w.@+-]+\\\\Z')\n    def validate(self, username):\n        if not self.regex.match(username):\n            raise ValueError('Invalid username')\nfixed_ascii_validator = FixedASCIIUsernameValidator()\nfixed_unicode_validator = FixedUnicodeUsernameValidator()\ntry:\n    fixed_ascii_validator.validate('validusername')\n    fixed_ascii_validator.validate('valid.username')\n    fixed_ascii_validator.validate('valid-username')\n    fixed_ascii_validator.validate('valid+username')\n    fixed_ascii_validator.validate('valid@username')\n    fixed_ascii_validator.validate('invalidusername\\n')\ntest_func('Issue reproduced')\nexcept ValueError:\ntest_func('Issue resolved')\nexcept Exception:\ntest_func('Other issues')\ntry:\n    fixed_unicode_validator.validate('validusername')\n    fixed_unicode_validator.validate('valid.username')\n    fixed_unicode_validator.validate('valid-username')\n    fixed_unicode_validator.validate('valid+username')\n    fixed_unicode_validator.validate('valid@username')\n    fixed_unicode_validator.validate('invalidusername\\n')\ntest_func('Issue reproduced')\nexcept ValueError:\ntest_func('Issue resolved')\nexcept Exception:\ntest_func('Other issues')\n(C) import re\ndef test_func():\n    regex_old = '^[\\\\w.@+-]+$'\n    regex_new = '\\\\A[\\\\w.@+-]+\\\\Z'\n    usernames = ['validUsername', 'valid.username@domain.com', 'invalidUsername\\n', 'invalidUsername\\nmoretext']\n    old_validator = re.compile(regex_old)\n    new_validator = re.compile(regex_new)\n    old_results = [bool(old_validator.match(username)) for username in usernames]\n    if not old_results[0] or not old_results[1] or old_results[2] or old_results[3]:\n        print('Other issues')\n        return\n    if old_results[2] or old_results[3]:\n        print('Issue reproduced')\n    else:\n        print('Issue not reproduced')\n    new_results = [bool(new_validator.match(username)) for username in usernames]\n    if new_results[0] and new_results[1] and (not new_results[2]) and (not new_results[3]):\n        print('Issue resolved')\n    else:\n        print('Other issues')\ntest_func()\n(D) import re\ndef test_func():\n    old_pattern = '^[\\\\w.@+-]+$'\n    new_pattern = '\\\\A[\\\\w.@+-]+\\\\Z'\n    test_username = 'username\\n'\n    if re.match(old_pattern, test_username):\n        print('Issue reproduced')\n    else:\n        print('Issue resolved')\n    if re.match(new_pattern, test_username):\n        print('Issue resolved')\n    else:\n        print('Issue reproduced')\ntest_func()
The answer is (D)

Question: Which is the correct test patch that can reproduce the issues described in the problem statement?
Problem statement: Autoreloader with StatReloader doesn't track changes in manage.py.\nDescription\n\t \n\t\t(last modified by Mariusz Felisiak)\n\t \nThis is a bit convoluted, but here we go.\nEnvironment (OSX 10.11):\n$ python -V\nPython 3.6.2\n$ pip -V\npip 19.1.1\n$ pip install Django==2.2.1\nSteps to reproduce:\nRun a server python manage.py runserver\nEdit the manage.py file, e.g. add print(): \ndef main():\n\tprint('sth')\n\tos.environ.setdefault('DJANGO_SETTINGS_MODULE', 'ticket_30479.settings')\n\t...\nUnder 2.1.8 (and prior), this will trigger the auto-reloading mechanism. Under 2.2.1, it won't. As far as I can tell from the django.utils.autoreload log lines, it never sees the manage.py itself.\n
Test patches: (A) import os\nimport subprocess\nimport time\nimport sys\ndef test_func():\n    manage_py_content = '\\nimport os\\nimport sys\\n\\ndef main():\\n    print(\\'sth\\')\\n    os.environ.setdefault(\\'DJANGO_SETTINGS_MODULE\\', \\'ticket_30479.settings\\')\\n    try:\\n        from django.core.management import execute_from_command_line\\n    except ImportError as exc:\\n        raise ImportError(\\n            \"Couldn\\'t import Django. Are you sure it\\'s installed and \"\\n            \"available on your PYTHONPATH environment variable? Did you \"\\n            \"forget to activate a virtual environment?\"\\n        ) from exc\\n    execute_from_command_line(sys.argv)\\n\\nif __name__ == \\'__main__\\':\\n    main()\\n'\n    try:\n        with open('manage.py', 'w') as file:\n            file.write(manage_py_content)\n        proc = subprocess.Popen([sys.executable, 'manage.py', 'runserver'], stdout=subprocess.PIPE, stderr=subprocess.PIPE)\n        time.sleep(5)\n        modified_manage_py_content = manage_py_content.replace(\"print('sth')\", \"print('modified')\")\n        with open('manage.py', 'w') as file:\n            file.write(modified_manage_py_content)\n        time.sleep(5)\n        output, error = proc.communicate(timeout=10)\n        output = output.decode('utf-8')\n        if 'modified' in output:\n            print('Issue resolved')\n        elif 'sth' in output:\n            print('Issue reproduced')\n        else:\n            print('Other issues')\n    except Exception as e:\n        print(f'Error occurred: {e}')\n    finally:\n        try:\n            proc.terminate()\n        except:\n            pass\ntest_func()\n(B) import os\nimport time\nimport subprocess\ndef test_func():\n    os.makedirs('ticket_30479', exist_ok=True)\n    with open('ticket_30479/manage.py', 'w') as f:\n        f.write('\\nimport os\\nimport sys\\n\\ndef main():\\n    os.environ.setdefault(\\'DJANGO_SETTINGS_MODULE\\', \\'ticket_30479.settings\\')\\n    try:\\n        from django.core.management import execute_from_command_line\\n    except ImportError as exc:\\n        raise ImportError(\\n            \"Couldn\\'t import Django. Are you sure it\\'s installed and \"\\n            \"available on your PYTHONPATH environment variable? Did you \"\\n            \"forget to activate a virtual environment?\"\\n        ) from exc\\n    execute_from_command_line(sys.argv)\\n\\nif __name__ == \\'__main__\\':\\n    main()\\n')\n    server_process = subprocess.Popen(['python', 'ticket_30479/manage.py', 'runserver'])\n    time.sleep(5)\n    with open('ticket_30479/manage.py', 'a') as f:\n        f.write(\"\\n    print('sth')\\n\")\n    time.sleep(10)\n    if server_process.poll() is None:\n        server_process.terminate()\n        print('Issue reproduced')\n    elif server_process.returncode == 0:\n        print('Issue resolved')\n    else:\n        print('Other issues')\n    try:\n        server_process.terminate()\n    except:\n        pass\n    os.remove('ticket_30479/manage.py')\n    os.rmdir('ticket_30479')\ntest_func()\n(C) import os\nimport subprocess\nimport time\ndef create_manage_py():\n    with open('manage.py', 'w') as file:\n        file.write('\\nimport os\\nimport sys\\n\\ndef main():\\n    os.environ.setdefault(\\'DJANGO_SETTINGS_MODULE\\', \\'ticket_30479.settings\\')\\n    try:\\n        from django.core.management import execute_from_command_line\\n    except ImportError as exc:\\n        raise ImportError(\\n            \"Couldn\\'t import Django. Are you sure it\\'s installed and \"\\n            \"available on your PYTHONPATH environment variable? Did you \"\\n            \"forget to activate a virtual environment?\"\\n        ) from exc\\n    execute_from_command_line(sys.argv)\\n\\nif __name__ == \\'__main__\\':\\n    main()\\n')\ndef modify_manage_py():\n    with open('manage.py', 'a') as file:\n        file.write(\"\\ndef main():\\n    print('sth')\\n    os.environ.setdefault('DJANGO_SETTINGS_MODULE', 'ticket_30479.settings')\\n\")\ndef start_server():\n    return subprocess.Popen(['python', 'manage.py', 'runserver'], stdout=subprocess.PIPE, stderr=subprocess.PIPE)\ndef test_autoreloader():\n    if not os.path.exists('manage.py'):\n        create_manage_py()\n    process = start_server()\n    time.sleep(5)\n    modify_manage_py()\n    time.sleep(5)\n    process.terminate()\n    stdout, stderr = process.communicate()\n    if b'sth' in stdout or b'sth' in stderr:\n        print('Issue resolved')\n    elif b'Error' in stderr or b'Traceback' in stderr:\n        print('Other issues')\n    else:\n        print('Issue reproduced')\nif __name__ == '__main__':\ntest_func()\n(D) import os\nimport subprocess\nimport time\nimport signal\ndef test_func():\n    os.system('django-admin startproject ticket_30479')\n    os.chdir('ticket_30479')\n    server = subprocess.Popen(['python', 'manage.py', 'runserver'], stdout=subprocess.PIPE, stderr=subprocess.PIPE)\n    time.sleep(5)\n    try:\n        with open('manage.py', 'a') as manage_py_file:\n            manage_py_file.write(\"\\nprint('sth')\\n\")\n        server.poll()\n        if server.returncode is not None:\n            print('Issue reproduced')\n        else:\n            print('Issue resolved')\n    except Exception as e:\n        print(f'Other issues: {e}')\n    finally:\n        if server.poll() is None:\n            os.kill(server.pid, signal.SIGINT)\n        os.chdir('..')\n        os.system('rm -rf ticket_30479')\ntest_func()
The answer is (A)

Question: Which is the correct test patch that can reproduce the issues described in the problem statement?
Problem statement: $PROBLEM$
Test patches: $CHOICES$
The answer is (